============================= test session starts ==============================
platform linux -- Python 3.10.15, pytest-8.3.3, pluggy-1.5.0
rootdir: /home/runner/work/fountainai-fastapi-proxy/fountainai-fastapi-proxy
plugins: anyio-4.5.0
collected 0 items / 1 error

==================================== ERRORS ====================================
______________________ ERROR collecting tests/test_app.py ______________________
ImportError while importing test module '/home/runner/work/fountainai-fastapi-proxy/fountainai-fastapi-proxy/tests/test_app.py'.
Hint: make sure your test modules/packages have valid Python names.
Traceback:
/opt/hostedtoolcache/Python/3.10.15/x64/lib/python3.10/importlib/__init__.py:126: in import_module
    return _bootstrap._gcd_import(name[level:], package, level)
tests/test_app.py:2: in <module>
    from app.main import app
app/main.py:2: in <module>
    from app.routers import logs, repo, traffic
app/routers/logs.py:2: in <module>
    from app.services.github_service import push_logs_to_github
E   ImportError: cannot import name 'push_logs_to_github' from 'app.services.github_service' (/home/runner/work/fountainai-fastapi-proxy/fountainai-fastapi-proxy/app/services/github_service.py)
=========================== short test summary info ============================
ERROR tests/test_app.py
!!!!!!!!!!!!!!!!!!!! Interrupted: 1 error during collection !!!!!!!!!!!!!!!!!!!!
=============================== 1 error in 0.35s ===============================
